Workbook

Sheet Cleaned_post_Data
A1: Post ID | B1: Platform | C1: Date | D1: Content Type | E1: Post Text | F1: Likes | G1: Shares | H1: Comments | I1: Impressions | J1: Reach | K1: Clicks | L1: Hashtags_Used_1 | M1: Hashtags_Used_2 | N1: Campaign_Name | O1: Engagement
A2: SP001 | B2: Instagram | C2: 45781 | D2: Text | E2: Discover fresh beats on Spotify! | F2: 2414 | G2: 245 | H2: 137 | I2: 21181 | J2: 45292 | K2: 133 | L2: #SoundtrackOfLife | M2: #NowPlaying | N2: ChillVibes | O2: =F2+G2+H2 -> 2796
A3: SP002 | B3: Instagram | C3: 45689 | D3: Text | E3: Explore the latest podcasts now. | F3: 1934 | G3: 210 | H3: 393 | I3: 29129 | J3: 73287 | K3: 273 | L3: #DiscoverWeekly | N3: IndieWave | O3: =F3+G3+H3 -> 2537
A4: SP003 | B4: Twitter | C4: 45629 | D4: Story | E4: New music just dropped. Hit play! | F4: 3092 | G4: 177 | H4: 81 | I4: 47533 | J4: 29220 | K4: 121 | L4: #MusicForEveryone | M4: #NowPlaying | N4: ChillVibes | O4: =F4+G4+H4 -> 3350
A5: SP004 | B5: Instagram | C5: 45629 | D5: Text | E5: Wrapped is here! Relive your top tracks ðŸŽ§ | F5: 3173 | G5: 229 | H5: 197 | I5: 29604 | J5: 21809 | K5: 272 | L5: #SoundtrackOfLife | M5: #NowPlaying | N5: ChillVibes | O5: =F5+G5+H5 -> 3599
A6: SP005 | B6: YouTube | C6: 45388 | D6: Text | E6: Music that moves youâ€”only on Spotify. | F6: 2748 | G6: 145 | H6: 315 | I6: 24401 | J6: 61182 | K6: 200 | L6: #DiscoverWeekly | M6: #SpotifyWrapped | N6: IndieWave | O6: =F6+G6+H6 -> 3208
A7: SP006 | B7: YouTube | C7: 45456 | D7: Text | E7: Whatâ€™s your vibe today? #SpotifyHits | F7: 3882 | G7: 239 | H7: 275 | I7: 58748 | J7: 44646 | K7: 149 | L7: #DiscoverWeekly | M7: #SpotifyWrapped | N7: IndieWave | O7: =F7+G7+H7 -> 4396
A8: SP007 | B8: Twitter | C8: 45645 | D8: Story | E8: Get into the groove with our new drop! | F8: 4674 | G8: 409 | H8: 327 | I8: 20756 | J8: 63599 | K8: 212 | L8: #SoundtrackOfLife | M8: #NowPlaying | N8: ChillVibes | O8: =F8+G8+H8 -> 5410
A9: SP008 | B9: Twitter | C9: 45421 | D9: Story | E9: Wrapped is here! Relive your top tracks ðŸŽ§ | F9: 1428 | G9: 347 | H9: 67 | I9: 21148 | J9: 19712 | K9: 120 | L9: #DiscoverWeekly | M9: #MusicForEveryone | N9: ChillVibes | O9: =F9+G9+H9 -> 1842
A10: SP009 | B10: Twitter | C10: 45823 | D10: Text | E10: Top trending tracks updated daily! | F10: 4432 | G10: 223 | H10: 299 | I10: 59016 | J10: 21742 | K10: 171 | L10: #NowPlaying | N10: ChillVibes | O10: =F10+G10+H10 -> 4954
A11: SP010 | B11: Twitter | C11: 45630 | D11: Text | E11: Wrapped is here! Relive your top tracks ðŸŽ§ | F11: 2357 | G11: 274 | H11: 172 | I11: 21566 | J11: 66829 | K11: 284 | L11: #NowPlaying | N11: ChillVibes | O11: =F11+G11+H11 -> 2803
A12: SP011 | B12: Twitter | C12: 45357 | D12: Text | E12: Discover fresh beats on Spotify! | F12: 1971 | G12: 370 | H12: 306 | I12: 31316 | J12: 27897 | K12: 88 | L12: #SoundtrackOfLife | N12: IndieWave | O12: =F12+G12+H12 -> 2647
A13: SP012 | B13: Instagram | C13: 45426 | D13: Text | E13: Discover fresh beats on Spotify! | F13: 1485 | G13: 353 | H13: 244 | I13: 38419 | J13: 38556 | K13: 86 | L13: #SoundtrackOfLife | M13: #NowPlaying | N13: ChillVibes | O13: =F13+G13+H13 -> 2082
A14: SP013 | B14: Twitter | C14: 45826 | D14: Story | E14: Discover fresh beats on Spotify! | F14: 3956 | G14: 319 | H14: 61 | I14: 58162 | J14: 28720 | K14: 213 | L14: #MusicForEveryone | M14: #NowPlaying | N14: ChillVibes | O14: =F14+G14+H14 -> 4336
A15: SP014 | B15: Twitter | C15: 45573 | D15: Text | E15: From pop to podcasts, itâ€™s all here. | F15: 2460 | G15: 409 | H15: 253 | I15: 36702 | J15: 46122 | K15: 264 | L15: #NowPlaying | N15: ChillVibes | O15: =F15+G15+H15 -> 3122
A16: SP015 | B16: Twitter | C16: 45418 | D16: Text | E16: Your weekend playlist is waiting. | F16: 3476 | G16: 355 | H16: 396 | I16: 37492 | J16: 27285 | K16: 179 | L16: #NowPlaying | N16: ChillVibes | O16: =F16+G16+H16 -> 4227
A17: SP016 | B17: Twitter | C17: 45655 | D17: Story | E17: New music just dropped. Hit play! | F17: 4049 | G17: 377 | H17: 94 | I17: 48182 | J17: 42875 | K17: 172 | L17: #MusicForEveryone | M17: #NowPlaying | N17: ChillVibes | O17: =F17+G17+H17 -> 4520
A18: SP017 | B18: Twitter | C18: 45453 | D18: Text | E18: Whatâ€™s your vibe today? #SpotifyHits | F18: 1514 | G18: 164 | H18: 275 | I18: 41364 | J18: 44389 | K18: 83 | L18: #NowPlaying | N18: ChillVibes | O18: =F18+G18+H18 -> 1953
A19: SP018 | B19: Instagram | C19: 45325 | D19: Story | E19: Music that moves youâ€”only on Spotify. | F19: 4281 | G19: 101 | H19: 163 | I19: 32278 | J19: 53382 | K19: 235 | L19: #NowPlaying | N19: Wrapped2024 | O19: =F19+G19+H19 -> 4545
A20: SP019 | B20: YouTube | C20: 45458 | D20: Reel | E20: Get into the groove with our new drop! | F20: 1751 | G20: 143 | H20: 151 | I20: 31826 | J20: 47729 | K20: 95 | L20: #DiscoverWeekly | M20: #SoundtrackOfLife | N20: SummerBeats | O20: =F20+G20+H20 -> 2045
A21: SP020 | B21: Instagram | C21: 45478 | D21: Text | E21: Your weekend playlist is waiting. | F21: 3753 | G21: 411 | H21: 308 | I21: 29138 | J21: 27678 | K21: 90 | L21: #DiscoverWeekly | N21: IndieWave | O21: =F21+G21+H21 -> 4472
A22: SP021 | B22: Instagram | C22: 45603 | D22: Story | E22: Wrapped is here! Relive your top tracks ðŸŽ§ | F22: 1678 | G22: 423 | H22: 323 | I22: 55668 | J22: 37945 | K22: 230 | L22: #NowPlaying | N22: Wrapped2024 | O22: =F22+G22+H22 -> 2424
A23: SP022 | B23: Instagram | C23: 45823 | D23: Text | E23: Whatâ€™s your vibe today? #SpotifyHits | F23: 4896 | G23: 466 | H23: 233 | I23: 28621 | J23: 34270 | K23: 84 | L23: #SoundtrackOfLife | M23: #NowPlaying | N23: ChillVibes | O23: =F23+G23+H23 -> 5595
A24: SP023 | B24: YouTube | C24: 45452 | D24: Reel | E24: From pop to podcasts, itâ€™s all here. | F24: 2786 | G24: 368 | H24: 208 | I24: 42000 | J24: 39967 | K24: 103 | L24: #DiscoverWeekly | M24: #SoundtrackOfLife | N24: SummerBeats | O24: =F24+G24+H24 -> 3362
A25: SP024 | B25: Twitter | C25: 45583 | D25: Text | E25: New music just dropped. Hit play! | F25: 2607 | G25: 379 | H25: 180 | I25: 28712 | J25: 61620 | K25: 174 | L25: #SoundtrackOfLife | N25: IndieWave | O25: =F25+G25+H25 -> 3166
A26: SP025 | B26: YouTube | C26: 45575 | D26: Reel | E26: From pop to podcasts, itâ€™s all here. | F26: 4013 | G26: 320 | H26: 92 | I26: 54605 | J26: 60169 | K26: 232 | L26: #DiscoverWeekly | M26: #SoundtrackOfLife | N26: SummerBeats | O26: =F26+G26+H26 -> 4425
A27: SP026 | B27: Twitter | C27: 45791 | D27: Story | E27: From pop to podcasts, itâ€™s all here. | F27: 2707 | G27: 103 | H27: 51 | I27: 55302 | J27: 18801 | K27: 147 | L27: #DiscoverWeekly | M27: #MusicForEveryone | N27: ChillVibes | O27: =F27+G27+H27 -> 2861
A28: SP027 | B28: Instagram | C28: 45625 | D28: Text | E28: Whatâ€™s your vibe today? #SpotifyHits | F28: 2824 | G28: 425 | H28: 274 | I28: 31004 | J28: 53488 | K28: 268 | L28: #SoundtrackOfLife | M28: #NowPlaying | N28: ChillVibes | O28: =F28+G28+H28 -> 3523
A29: SP028 | B29: YouTube | C29: 45356 | D29: Reel | E29: Explore the latest podcasts now. | F29: 3558 | G29: 314 | H29: 199 | I29: 49612 | J29: 53929 | K29: 206 | L29: #DiscoverWeekly | M29: #SoundtrackOfLife | N29: SummerBeats | O29: =F29+G29+H29 -> 4071
A30: SP029 | B30: Twitter | C30: 45734 | D30: Story | E30: Explore the latest podcasts now. | F30: 3418 | G30: 188 | H30: 387 | I30: 57431 | J30: 36933 | K30: 202 | L30: #MusicForEveryone | M30: #NowPlaying | N30: ChillVibes | O30: =F30+G30+H30 -> 3993
A31: SP030 | B31: Twitter | C31: 45773 | D31: Text | E31: Discover fresh beats on Spotify! | F31: 2411 | G31: 194 | H31: 168 | I31: 26665 | J31: 71699 | K31: 197 | L31: #NowPlaying | N31: ChillVibes | O31: =F31+G31+H31 -> 2773
A32: SP031 | B32: Instagram | C32: 45658 | D32: Text | E32: New music just dropped. Hit play! | F32: 4036 | G32: 112 | H32: 382 | I32: 56284 | J32: 29440 | K32: 279 | L32: #SoundtrackOfLife | M32: #NowPlaying | N32: ChillVibes | O32: =F32+G32+H32 -> 4530
A33: SP032 | B33: Twitter | C33: 45419 | D33: Story | E33: Explore the latest podcasts now. | F33: 2776 | G33: 307 | H33: 178 | I33: 43365 | J33: 48408 | K33: 138 | L33: #SoundtrackOfLife | M33: #NowPlaying | N33: ChillVibes | O33: =F33+G33+H33 -> 3261
A34: SP033 | B34: Twitter | C34: 45574 | D34: Story | E34: Discover fresh beats on Spotify! | F34: 4929 | G34: 182 | H34: 95 | I34: 32181 | J34: 31084 | K34: 289 | L34: #DiscoverWeekly | M34: #MusicForEveryone | N34: ChillVibes | O34: =F34+G34+H34 -> 5206
A35: SP034 | B35: Instagram | C35: 45666 | D35: Text | E35: New music just dropped. Hit play! | F35: 1015 | G35: 366 | H35: 308 | I35: 38127 | J35: 63790 | K35: 287 | L35: #SoundtrackOfLife | M35: #NowPlaying | N35: ChillVibes | O35: =F35+G35+H35 -> 1689
A36: SP035 | B36: Twitter | C36: 45785 | D36: Story | E36: Your weekend playlist is waiting. | F36: 3316 | G36: 332 | H36: 268 | I36: 40095 | J36: 36913 | K36: 265 | L36: #MusicForEveryone | M36: #NowPlaying | N36: ChillVibes | O36: =F36+G36+H36 -> 3916
A37: SP036 | B37: Instagram | C37: 45416 | D37: Text | E37: Wrapped is here! Relive your top tracks ðŸŽ§ | F37: 2274 | G37: 243 | H37: 222 | I37: 43066 | J37: 59174 | K37: 80 | L37: #DiscoverWeekly | N37: IndieWave | O37: =F37+G37+H37 -> 2739
A38: SP037 | B38: Twitter | C38: 45804 | D38: Story | E38: Explore the latest podcasts now. | F38: 4095 | G38: 385 | H38: 400 | I38: 45300 | J38: 31795 | K38: 80 | L38: #MusicForEveryone | M38: #NowPlaying | N38: ChillVibes | O38: =F38+G38+H38 -> 4880
A39: SP038 | B39: Instagram | C39: 45545 | D39: Story | E39: New music just dropped. Hit play! | F39: 1230 | G39: 309 | H39: 207 | I39: 44629 | J39: 40699 | K39: 195 | L39: #NowPlaying | N39: Wrapped2024 | O39: =F39+G39+H39 -> 1746
A40: SP039 | B40: Instagram | C40: 45621 | D40: Text | E40: From pop to podcasts, itâ€™s all here. | F40: 1341 | G40: 472 | H40: 238 | I40: 51386 | J40: 51706 | K40: 133 | L40: #DiscoverWeekly | N40: IndieWave | O40: =F40+G40+H40 -> 2051
...

Sheet Cleaned_Engagement_Data 
A1: Week_Start_Date | B1: Platform | C1: New_Followers | D1: Unfollows | E1: Total_Followers | F1: Engagement_Rate | G1: Ad_Spend | H1: Net followers | I1: Growth Rate (%)
A2: 45446 | B2: Instagram | C2: 1402 | D2: 68 | E2: 124562 | F2: 9.92 | G2: 23125 | H2: =C2-D2 -> 1334 | I2: =H2/E2 -> 0.010709526
A3: 45446 | B3: Twitter | C3: 995 | D3: 86 | E3: 227958 | F3: 8.05 | G3: 22788 | H3: =C3-D3 -> 909 | I3: =H3/E3 -> 0.0039875767
A4: 45446 | B4: YouTube | C4: 1472 | D4: 296 | E4: 370242 | F4: 7.72 | G4: 7810 | H4: =C4-D4 -> 1176 | I4: =H4/E4 -> 0.0031763009 | K4: Growth Rate Formula
A5: 45453 | B5: Instagram | C5: 1018 | D5: 90 | E5: 92474 | F5: 9.4 | G5: 11966 | H5: =C5-D5 -> 928 | I5: =H5/E5 -> 0.010035253
A6: 45453 | B6: Twitter | C6: 1461 | D6: 64 | E6: 328902 | F6: 9.02 | G6: 26298 | H6: =C6-D6 -> 1397 | I6: =H6/E6 -> 0.0042474658 | K6: Growth rate (%) | M6: New follower -Unfollower | O6: *100
A7: 45453 | B7: YouTube | C7: 545 | D7: 93 | E7: 391621 | F7: 9.96 | G7: 22029 | H7: =C7-D7 -> 452 | I7: =H7/E7 -> 0.0011541771 | M7: Total Follower
A8: 45460 | B8: Instagram | C8: 881 | D8: 291 | E8: 95885 | F8: 5.29 | G8: 12391 | H8: =C8-D8 -> 590 | I8: =H8/E8 -> 0.0061532044
A9: 45460 | B9: Twitter | C9: 1414 | D9: 131 | E9: 245947 | F9: 8.3 | G9: 14477 | H9: =C9-D9 -> 1283 | I9: =H9/E9 -> 0.005216571
A10: 45460 | B10: YouTube | C10: 1472 | D10: 170 | E10: 250428 | F10: 4.66 | G10: 25040 | H10: =C10-D10 -> 1302 | I10: =H10/E10 -> 0.0051990991
A11: 45467 | B11: Instagram | C11: 809 | D11: 197 | E11: 87186 | F11: 9.48 | G11: 22619 | H11: =C11-D11 -> 612 | I11: =H11/E11 -> 0.0070194756
A12: 45467 | B12: Twitter | C12: 1371 | D12: 250 | E12: 128620 | F12: 7.11 | G12: 12399 | H12: =C12-D12 -> 1121 | I12: =H12/E12 -> 0.0087155963
A13: 45467 | B13: YouTube | C13: 844 | D13: 144 | E13: 126015 | F13: 9.65 | G13: 22456 | H13: =C13-D13 -> 700 | I13: =H13/E13 -> 0.0055548943
A14: 45474 | B14: Instagram | C14: 786 | D14: 72 | E14: 178615 | F14: 5.43 | G14: 19328 | H14: =C14-D14 -> 714 | I14: =H14/E14 -> 0.0039974246
A15: 45474 | B15: Twitter | C15: 845 | D15: 250 | E15: 218228 | F15: 4.52 | G15: 21107 | H15: =C15-D15 -> 595 | I15: =H15/E15 -> 0.0027265062
A16: 45474 | B16: YouTube | C16: 1218 | D16: 101 | E16: 300397 | F16: 4.33 | G16: 12277 | H16: =C16-D16 -> 1117 | I16: =H16/E16 -> 0.0037184126
A17: 45481 | B17: Instagram | C17: 797 | D17: 130 | E17: 340121 | F17: 8.52 | G17: 11684 | H17: =C17-D17 -> 667 | I17: =H17/E17 -> 0.0019610668
A18: 45481 | B18: Twitter | C18: 1471 | D18: 100 | E18: 76866 | F18: 8.55 | G18: 14412 | H18: =C18-D18 -> 1371 | I18: =H18/E18 -> 0.017836234
A19: 45481 | B19: YouTube | C19: 1253 | D19: 136 | E19: 193131 | F19: 7.99 | G19: 15924 | H19: =C19-D19 -> 1117 | I19: =H19/E19 -> 0.0057836391
... A201: 45908 | B201: Twitter | C201: 860 | D201: 244 | E201: 348686 | F201: 5.12 | G201: 11418 | H201: =C201-D201 -> 616 | I201: =H201/E201 -> 0.0017666324

Sheet  Highest Engagement 
G2: Task 3: Platform Performance Analysis
G4: 1 . Determine which platform yields highest Engagement
G6: Determine which Platform yields Highest Engagement
G7: Platform | H7: Sum of Engagement
G8: Twitter | H8: 527370
G9: Instagram | H9: 301576 | J9: Based on Platform analysis ,Twitter yields the Highest Engagement with a total score (52,7370), outperforming both Instagram and Twitter . Increase investement on twitter and improve strategy on instagram and youtube
G10: YouTube | H10: 228696
G11: Grand Total | H11: 1057642

Sheet Compare Weekly Follower
C2: Task 3 | G2: Compare weekly follower growth rates across platforms
B4: 2. Compare weekly follower growth rates across platforms
B6: Compare weekly follower growth rates across platforms
B7: Average of Growth Rate (%) | C7: Platform Labels
B8: Week_Start_Date | C8: Instagram | D8: Twitter | E8: YouTube
B9: 45446 | C9: 0.010709526 | D9: 0.0039875767 | E9: 0.0031763009
B10: 45453 | C10: 0.010035253 | D10: 0.0042474658 | E10: 0.0011541771
B11: 45460 | C11: 0.0061532044 | D11: 0.005216571 | E11: 0.0051990991
B12: 45467 | C12: 0.0070194756 | D12: 0.0087155963 | E12: 0.0055548943
B13: 45474 | C13: 0.0039974246 | D13: 0.0027265062 | E13: 0.0037184126
B14: 45481 | C14: 0.0019610668 | D14: 0.017836234 | E14: 0.0057836391
B15: 45488 | C15: 0.0021159343 | D15: 0.0041633647 | E15: 0.0044074792
B16: 45495 | C16: 0.0038800515 | D16: 0.0013666229 | E16: 0.0029558126
B17: 45502 | C17: 0.0023089718 | D17: 0.0052125958 | E17: 0.0024107128
B18: 45509 | C18: 0.0067435555 | D18: 0.0043839826 | E18: 0.0023829134
B19: 45516 | C19: 0.014216285 | D19: 0.010311242 | E19: 0.0032668165
B20: 45523 | C20: 0.0025711522 | D20: 0.006216942 | E20: 0.0061138546
... B74: 45901 | C74: 0.0031996008 | D74: 0.003671063 | E74: 0.00079729049
B75: 45908 | C75: 0.0091194199 | D75: 0.0017666324
B76: Grand Total | C76: 0.0043506104 | D76: 0.0046999265 | E76: 0.0039495608
G78: In Data set 2025-09-08 only post instgram and twiitter Platform

Sheet Ad Spend vs Engagement
E2: Task 3 | H2: Visualize Ad Spend vs. Engagement using charts
C4: 3 .Visualize Ad Spend vs. Engagement using charts
D6: Visualize Ad Spend vs. Engagement using charts | S6: Formula & Function used for this Task
D7: Platform | E7: Total Engagement | F7: Total Ad spend | S7: formula /function | T7: Purpose
D8: {=_xlfn.UNIQUE(Cleaned_post_Data!B2:B301)} -> Instagram | E8: =SUMIF(Cleaned_post_Data!$B$2:$B$301,'Ad Spend vs Engagement'!D8,Cleaned_post_Data!$O$2:$O$301) -> 301576 | F8: =SUMIF('Cleaned_Engagement_Data '!$B$2:$B$201,'Ad Spend vs Engagement'!D8,'Cleaned_Engagement_Data '!$G$2:$G$201) -> 1035942 | S8: =UNIQUE | T8: for Platform
D9: Twitter | E9: =SUMIF(Cleaned_post_Data!$B$2:$B$301,'Ad Spend vs Engagement'!D9,Cleaned_post_Data!$O$2:$O$301) -> 527370 | F9: =SUMIF('Cleaned_Engagement_Data '!$B$2:$B$201,'Ad Spend vs Engagement'!D9,'Cleaned_Engagement_Data '!$G$2:$G$201) -> 1114204 | S9: =SUMIF | T9: Calculate Total Engagement
D10: YouTube | E10: =SUMIF(Cleaned_post_Data!$B$2:$B$301,'Ad Spend vs Engagement'!D10,Cleaned_post_Data!$O$2:$O$301) -> 228696 | F10: =SUMIF('Cleaned_Engagement_Data '!$B$2:$B$201,'Ad Spend vs Engagement'!D10,'Cleaned_Engagement_Data '!$G$2:$G$201) -> 1065782 | S10: =SUMIF | T10: Calculate Total Ad spend
B13: Twitter provides the Highest total Engagement (527,370) with a spend of ₹11.14 Lakh.
B14: It is the most cost-effective platform, sitting at the top of the scatter chart.
B15: Twitter is currently our most successful Twitter for driving big results.
B18: Both Instagram and YouTube platforms have a similar ad spend (around ₹10.3L - ₹10.6L).
B19: ​ Even with almost the same budget, Instagram delivers much Higher Engagement (301,576)
B20: than YouTube (228,696).
B21: YouTube has the lowest total engagement despite having a higher spend than Instagram.
B22: We should review our YouTube strategy as it is giving the lowest return for every Rupee spent

Sheet  Recommend Platform
A1: Recommend focusing on 1–2 Platforms or Continuing multi-Platform Justify with Data
L3: final Analysis Based on Data
B4: Determine which Platform yields Highest Engagement | L4: 1. Highest Engagement Platform : Twitter at (52,7370) interaction
B5: Platform | C5: Sum of Engagement | L5: 2. Highest Net Growth Rate : Twitter 0.47%
B6: Twitter | C6: 527370
B7: Instagram | C7: 301576 | E7: Based on Platform analysis ,Twitter yields the Highest Engagement with a total score (52,7370), outperforming both Instagram and Twitter . Increase investement on twitter and improve strategy on instagram and youtube
B8: YouTube | C8: 228696 | L8: Recommended focusing on one primary platform supported by a secondary platform. Twitter shows the highest performance across key metrics, while Instagram also performs well with close results. Therefore, Twitter should be the main focus, with Instagram used as a supporting platform to maximize overall performance. This way, we get good results and don’t depend on only one platform.
B9: Grand Total | C9: 1057642
B13: Compare weekly follower growth rates across platforms
B14: Week_Start_Date | C14: Average of Growth Rate (%)
B15: Instagram | C15: 0.0043506104 | E15: Twitter Had the Highest Average of Growth Rate(%) 0.47% Indicatin weekly top Performing Platform compare to other platforms
B16: Twitter | C16: 0.0046999265
B17: YouTube | C17: 0.0039495608
B20: Visualize Ad Spend vs. Engagement using charts
B21: Platform | C21: Total Engagement | D21: Total Ad spend | F21: Twitter provides the Highest total Engagement (527,370) with a spend of ₹11.14 Lakh.
B22: Instagram | C22: 301576 | D22: 1035942
B23: Twitter | C23: 527370 | D23: 1114204
B24: YouTube | C24: 228696 | D24: 1065782

Sheet Raw_Posts
A1: Post ID | B1: Platform | C1: Date | D1: Content Type | E1: Post Text | F1: Likes | G1: Shares | H1: Comments | I1: Impressions | J1: Reach | K1: Clicks | L1: Hashtags Used | M1: Campaign_Name
A2: SP001 | B2: Instagram | C2: 45781 | D2: Text | E2: Discover fresh beats on Spotify! | F2: 2414 | G2: 245 | H2: 137 | I2: 21181 | J2: 45292 | K2: 133 | L2: #SoundtrackOfLife,#NowPlaying | M2: ChillVibes
A3: SP002 | B3: Instagram | C3: 45689 | D3: Text | E3: Explore the latest podcasts now. | F3: 1934 | G3: 210 | H3: 393 | I3: 29129 | J3: 73287 | K3: 273 | L3: #DiscoverWeekly | M3: IndieWave
A4: SP003 | B4: Twitter | C4: 45629 | D4: Story | E4: New music just dropped. Hit play! | F4: 3092 | G4: 177 | H4: 81 | I4: 47533 | J4: 29220 | K4: 121 | L4: #MusicForEveryone,#NowPlaying | M4: ChillVibes
A5: SP004 | B5: Instagram | C5: 45629 | D5: Text | E5: Wrapped is here! Relive your top tracks ðŸŽ§ | F5: 3173 | G5: 229 | H5: 197 | I5: 29604 | J5: 21809 | K5: 272 | L5: #SoundtrackOfLife,#NowPlaying | M5: ChillVibes
A6: SP005 | B6: YouTube | C6: 45388 | D6: Text | E6: Music that moves youâ€”only on Spotify. | F6: 2748 | G6: 145 | H6: 315 | I6: 24401 | J6: 61182 | K6: 200 | L6: #DiscoverWeekly,#SpotifyWrapped | M6: IndieWave
A7: SP006 | B7: YouTube | C7: 45456 | D7: Text | E7: Whatâ€™s your vibe today? #SpotifyHits | F7: 3882 | G7: 239 | H7: 275 | I7: 58748 | J7: 44646 | K7: 149 | L7: #DiscoverWeekly,#SpotifyWrapped | M7: IndieWave
A8: SP007 | B8: Twitter | C8: 45645 | D8: Story | E8: Get into the groove with our new drop! | F8: 4674 | G8: 409 | H8: 327 | I8: 20756 | J8: 63599 | K8: 212 | L8: #SoundtrackOfLife,#NowPlaying | M8: ChillVibes
A9: SP008 | B9: Twitter | C9: 45421 | D9: Story | E9: Wrapped is here! Relive your top tracks ðŸŽ§ | F9: 1428 | G9: 347 | H9: 67 | I9: 21148 | J9: 19712 | K9: 120 | L9: #DiscoverWeekly,#MusicForEveryone | M9: ChillVibes
A10: SP009 | B10: Twitter | C10: 45823 | D10: Text | E10: Top trending tracks updated daily! | F10: 4432 | G10: 223 | H10: 299 | I10: 59016 | J10: 21742 | K10: 171 | L10: #NowPlaying | M10: ChillVibes
A11: SP010 | B11: Twitter | C11: 45630 | D11: Text | E11: Wrapped is here! Relive your top tracks ðŸŽ§ | F11: 2357 | G11: 274 | H11: 172 | I11: 21566 | J11: 66829 | K11: 284 | L11: #NowPlaying | M11: ChillVibes
A12: SP011 | B12: Twitter | C12: 45357 | D12: Text | E12: Discover fresh beats on Spotify! | F12: 1971 | G12: 370 | H12: 306 | I12: 31316 | J12: 27897 | K12: 88 | L12: #SoundtrackOfLife | M12: IndieWave
A13: SP012 | B13: Instagram | C13: 45426 | D13: Text | E13: Discover fresh beats on Spotify! | F13: 1485 | G13: 353 | H13: 244 | I13: 38419 | J13: 38556 | K13: 86 | L13: #SoundtrackOfLife,#NowPlaying | M13: ChillVibes
... A301: SP300 | B301: Instagram | C301: 45329 | D301: Text | E301: Music that moves youâ€”only on Spotify. | F301: 1883 | G301: 432 | H301: 397 | I301: 28759 | J301: 18691 | K301: 270 | L301: #SoundtrackOfLife,#NowPlaying | M301: ChillVibes

Sheet Raw_Engagement 
A1: Week_Start_Date | B1: Platform | C1: New_Followers | D1: Unfollows | E1: Total_Followers | F1: Engagement_Rate | G1: Ad_Spend
A2: 45446 | B2: Instagram | C2: 1402 | D2: 68 | E2: 124562 | F2: 9.92 | G2: 23125
A3: 45446 | B3: Twitter | C3: 995 | D3: 86 | E3: 227958 | F3: 8.05 | G3: 22788
A4: 45446 | B4: YouTube | C4: 1472 | D4: 296 | E4: 370242 | F4: 7.72 | G4: 7810
A5: 45453 | B5: Instagram | C5: 1018 | D5: 90 | E5: 92474 | F5: 9.4 | G5: 11966
A6: 45453 | B6: Twitter | C6: 1461 | D6: 64 | E6: 328902 | F6: 9.02 | G6: 26298
A7: 45453 | B7: YouTube | C7: 545 | D7: 93 | E7: 391621 | F7: 9.96 | G7: 22029
A8: 45460 | B8: Instagram | C8: 881 | D8: 291 | E8: 95885 | F8: 5.29 | G8: 12391
A9: 45460 | B9: Twitter | C9: 1414 | D9: 131 | E9: 245947 | F9: 8.3 | G9: 14477
A10: 45460 | B10: YouTube | C10: 1472 | D10: 170 | E10: 250428 | F10: 4.66 | G10: 25040
A11: 45467 | B11: Instagram | C11: 809 | D11: 197 | E11: 87186 | F11: 9.48 | G11: 22619
A12: 45467 | B12: Twitter | C12: 1371 | D12: 250 | E12: 128620 | F12: 7.11 | G12: 12399
A13: 45467 | B13: YouTube | C13: 844 | D13: 144 | E13: 126015 | F13: 9.65 | G13: 22456
... A201: 45908 | B201: Twitter | C201: 860 | D201: 244 | E201: 348686 | F201: 5.12 | G201: 11418

Sheet Raw-Campaign 
A1: Campaign_Name | B1: Start_Date | C1: End_Date | D1: Objective | E1: Total_Budget | F1: Target_Platforms | G1: Primary_Hashtags
A2: SummerBeats | B2: 2024-06-15 | C2: 2024-07-15 | D2: Brand Awareness | E2: 175000 | F2: Instagram,YouTube | G2: #SpotifyWrapped,#MusicForEveryone
A3: Wrapped2024 | B3: 2024-12-01 | C3: 2024-12-31 | D3: Engagement | E3: 225000 | F3: Twitter,YouTube | G3: #SpotifyWrapped,#NowPlaying
A4: ChillVibes | B4: 2025-01-10 | C4: 2025-02-10 | D4: Product Launch | E4: 200000 | F4: Instagram,Twitter | G4: #ChillVibes,#SoundtrackOfLife
A5: IndieWave | B5: 2025-03-01 | C5: 2025-03-31 | D5: Traffic | E5: 160000 | F5: Facebook,Instagram | G5: #DiscoverWeekly,#IndieWave
